Workbook

Sheet Llegenda
A1: SUPERMANAGER MCBF 26/27 — Full de dades
A3: Pestanyes on cal escriure/editar manualment:
A4: Doblatges | B4: Actualitzar cada setmana amb la llista de jugadores que dobles i a quin equip.
A5: Jornades | B5: Marcar quins equips juguen aquesta jornada (Actiu_...) i les preguntes/respostes correctes.
A6: Partits | B6: Escriure V o D per cada equip un cop acabada la jornada (per calcular el bonus del 20%).
A7: Resultats_jugadores | B7: Introduir punts i faltes de cada jugadora un cop jugada la jornada.
A8: Respostes_usuari | B8: Puntuar manualment la columna Punts_preguntes (5 o 20 punts segons la normativa).
A10: Pestanyes que escriurà l'app automàticament:
A11: Equips_usuari | B11: Cada equip que un usuari envia (l'app hi escriu directament).
A12: Jugadores | B12: (no la toca l'app; és el mestre de dades)
A14: Pestanyes calculades — NO editar a mà:
A15: Calcul_puntuacio
A16: Classificacio
A17: Classificacio_global

Sheet Jugadores
A1: Nom | B1: Equip | C1: Posicio | D1: Estrella
A2: Anna Fornells | B2: LF2 | C2: A | D2: NO
A3: Queralt Ribera | B3: LF2 | C3: A | D3: NO
A4: Clàudia Morros | B4: LF2 | C4: A | D4: NO
A5: Mar Ribera | B5: LF2 | C5: A | D5: NO
A6: Andreea Cojocariu | B6: LF2 | C6: A | D6: SI
A7: Mar Martí | B7: LF2 | C7: A | D7: NO
A8: Sira Gaspà | B8: LF2 | C8: B | D8: NO
A9: Marina Melero | B9: LF2 | C9: B | D9: SI
A10: Ayisse Magassa | B10: LF2 | C10: P | D10: NO
A11: Emma Pey | B11: LF2 | C11: P | D11: NO
A12: Eva Almasqué | B12: LF2 | C12: P | D12: NO
... A69: Laia Serra | B69: U18 | C69: P | D69: SI

Sheet Doblatges
A1: Jornada | B1: Nom | C1: Equip_origen | D1: Equip_dobla | E1: Posicio
A2: 1 | B2: Ainara Cedres | C2: (fora del roster / altra categoria) | D2: U13 | E2: B
A3: 1 | B3: Esrae El Harraq | C3: (fora del roster / altra categoria) | D3: U13 | E3: B
A4: 1 | B4: Elna Leon | C4: (fora del roster / altra categoria) | D4: U13 | E4: A
A5: 1 | B5: Martina Agramunt | C5: U13 | D5: U14 | E5: B
A6: 1 | B6: Clàudia Barcons | C6: U13 | D6: U14 | E6: A
A7: 1 | B7: Aina Torras | C7: U13 | D7: U14 | E7: P
A8: 1 | B8: Violant Vinyes | C8: U14 | D8: U15 | E8: B
A9: 1 | B9: Ndeye Diop | C9: U14 | D9: U15 | E9: A
A10: 1 | B10: Abril Pérez | C10: U14 | D10: U15 | E10: A
A11: 1 | B11: Leyre Castelló | C11: U14 | D11: U15 | E11: P
A12: 1 | B12: Nina Clotet | C12: U16 | D12: U17 | E12: B
A13: 1 | B13: Iria Sastre | C13: U16 | D13: U17 | E13: B
... A20: 1 | B20: Sara Primo | C20: U16 | D20: U17 | E20: P

Sheet Jornades
A1: Jornada | B1: Actiu_U13 | C1: Actiu_U14 | D1: Actiu_U15 | E1: Actiu_U16 | F1: Actiu_U17 | G1: Actiu_U18 | H1: Actiu_LF2 | I1: Pregunta_average | J1: Resposta_correcta_average | K1: Pregunta_2 | L1: Resposta_correcta_2 | M1: Pregunta_3 | N1: Resposta_correcta_3 | O1: Mostrar_equips
A2: 1 | B2: si | C2: no | D2: si | E2: si | F2: si | G2: si | H2: si | I2: De quin marge guanyarà el SFB? | K2: De quin marge guanyarà el SFB? | O2: SI

Sheet Partits
A1: Jornada | B1: Equip | C1: Resultat | D1: Clau | E1: Resultat: escriure V (victoria) o D (derrota)
A2: 1 | B2: U13 | C2: V | D2: =A2&"_"&B2 -> 1_U13
A3: 1 | B3: U14 | C3: V | D3: =A3&"_"&B3 -> 1_U14
A4: 1 | B4: U15 | C4: V | D4: =A4&"_"&B4 -> 1_U15
A5: 1 | B5: U16 | C5: V | D5: =A5&"_"&B5 -> 1_U16
A6: 1 | B6: U17 | C6: V | D6: =A6&"_"&B6 -> 1_U17
A7: 1 | B7: U18 | C7: V | D7: =A7&"_"&B7 -> 1_U18
A8: 1 | B8: LF2 | C8: V | D8: =A8&"_"&B8 -> 1_LF2

Sheet Resultats_jugadores
A1: Jornada | B1: Nom | C1: Punts | D1: Faltes
A2: 1 | B2: Anna Fornells | C2: 10 | D2: 2
A3: 1 | B3: Queralt Ribera | C3: 2 | D3: 2
A4: 1 | B4: Clàudia Morros | C4: 0 | D4: 3
A5: 1 | B5: Mar Ribera | C5: 11 | D5: 6
A6: 1 | B6: Andreea Cojocariu | C6: 2 | D6: 3
A7: 1 | B7: Mar Martí | C7: 9 | D7: 1
A8: 1 | B8: Sira Gaspà | C8: 4 | D8: 2
A9: 1 | B9: Marina Melero | C9: 16 | D9: 3
A10: 1 | B10: Ayisse Magassa | C10: 5 | D10: 2
A11: 1 | B11: Emma Pey | C11: 6 | D11: 1
A12: 1 | B12: Eva Almasqué | C12: 0 | D12: 0
A13: 1 | B13: Jana Calvet | C13: 4 | D13: 1
... A22: 1 | B22: Arya Miquel | C22: 4 | D22: 1
A23: 1 | B23: Greta Codina
A24: 1 | B24: Emma Escudé
A25: 1 | B25: Ndeye Diop
A26: 1 | B26: Anouk Mas
A27: 1 | B27: Abril Pérez
A28: 1 | B28: Ariadna Cartes
A29: 1 | B29: Edurne Marco
A30: 1 | B30: Violant Vinyes
A31: 1 | B31: Leyre Castelló
A32: 1 | B32: Abril Parés
A33: 1 | B33: Laia Castells
A34: 1 | B34: Erica Farizo
... A58: 1 | B58: Anna Guix
A59: 1 | B59: Laia Llamas | C59: 4 | D59: 1
A60: 1 | B60: Aina Muñoz | C60: 0 | D60: 0
A61: 1 | B61: Carla Forcada | C61: 0 | D61: 0
A62: 1 | B62: Júlia Arcos | C62: 8 | D62: 2
A63: 1 | B63: Mariona Rosell | C63: 2 | D63: 2
A64: 1 | B64: Xènia Fígols | C64: 24 | D64: 2
A65: 1 | B65: Kourafy Dembele | C65: 10 | D65: 2
A66: 1 | B66: Berta Gol | C66: 3 | D66: 3
A67: 1 | B67: Mbakourou Dembele | C67: 7 | D67: 3
A68: 1 | B68: Carla Dalmau | C68: 0 | D68: 0
A69: 1 | B69: Laia Serra | C69: 6 | D69: 2

Sheet Equips_usuari
A1: Jornada | B1: Usuari | C1: Jugadora | D1: Equip_jugadora | E1: Posicio | F1: Capitana | G1: Timestamp
A2: 1 | B2: U15 | C2: Marina Melero | D2: LF2 | E2: B | F2: NO | G2: 46288.371
A3: 1 | B3: U15 | C3: Martina Agramunt | D3: U13 | E3: B | F3: NO | G3: 46288.371
A4: 1 | B4: U15 | C4: Kourafy Dembele | D4: U18 | E4: B | F4: NO | G4: 46288.371
A5: 1 | B5: U15 | C5: Clàudia Barcons | D5: U13 | E5: A | F5: NO | G5: 46288.371
A6: 1 | B6: U15 | C6: Eulàlia Mayor | D6: U16 | E6: A | F6: NO | G6: 46288.371
A7: 1 | B7: U15 | C7: Xènia Fígols | D7: U18 | E7: A | F7: NO | G7: 46288.371
A8: 1 | B8: U15 | C8: Aina Torras | D8: U13 | E8: P | F8: SI | G8: 46288.371
A9: 1 | B9: U15 | C9: Leyre Castelló | D9: U15 | E9: P | F9: NO | G9: 46288.371
A10: 1 | B10: U15 | C10: Laia Muncunill | D10: U17 | E10: P | F10: NO | G10: 46288.371
A11: 1 | B11: U17+SFB | C11: Nina Clotet | D11: U16 | E11: B | F11: NO | G11: 46289.086
A12: 1 | B12: U17+SFB | C12: Erica Farizo | D12: U15 | E12: B | F12: NO | G12: 46289.086
A13: 1 | B13: U17+SFB | C13: Marina Melero | D13: LF2 | E13: B | F13: SI | G13: 46289.086
... A64: 1 | B64: U18+DE | C64: Laia Serra | D64: U18 | E64: P | F64: NO | G64: 46289.095

Sheet Respostes_usuari
A1: Jornada | B1: Usuari | C1: Resposta_average | D1: Resposta_2 | E1: Resposta_3 | F1: Punts_preguntes

Sheet Calcul_puntuacio
A1: Jornada | B1: Usuari | C1: Jugadora | D1: Equip_jugadora | E1: Capitana | F1: Punts | G1: Faltes | H1: Punts_base | I1: Resultat_equip | J1: Bonus_multiplicador | K1: Punts_amb_bonus | L1: Multiplicador_capitana | M1: Punts_final
A2: =IF(#REF!="","",#REF!) -> #REF! | B2: =IF(#REF!="","",#REF!) -> #REF! | C2: =IF(#REF!="","",#REF!) -> #REF! | D2: =IF(#REF!="","",#REF!) -> #REF! | E2: =IF(#REF!="","",#REF!) -> #REF! | F2: =IF($C2="","",SUMIFS(Resultats_jugadores!$C:$C,Resultats_jugadores!$A:$A,$A2,Resultats_jugadores!$B:$B,$C2)) -> #REF! | G2: =IF($C2="","",SUMIFS(Resultats_jugadores!$D:$D,Resultats_jugadores!$A:$A,$A2,Resultats_jugadores!$B:$B,$C2)) -> #REF! | H2: =IF($C2="","",N($F2)-N($G2)) -> #REF! | I2: {=IF($C2="","",IFERROR(INDEX(Partits!$C:$C,MATCH($A2&"_"&$D2,Partits!$D:$D,0)),""))} -> #REF! | J2: =IF($C2="","",IF(AND($I2="V",N($H2)>0),1.2,1)) -> #REF! | K2: =IF($C2="","",N($H2)*$J2) -> #REF! | L2: =IF($C2="","",IF($E2="SI",2,1)) -> #REF! | M2: =IF($C2="","",$K2*$L2) -> #REF!
A3: =IF(#REF!="","",#REF!) -> #REF! | B3: =IF(#REF!="","",#REF!) -> #REF! | C3: =IF(#REF!="","",#REF!) -> #REF! | D3: =IF(#REF!="","",#REF!) -> #REF! | E3: =IF(#REF!="","",#REF!) -> #REF! | F3: =IF($C3="","",SUMIFS(Resultats_jugadores!$C:$C,Resultats_jugadores!$A:$A,$A3,Resultats_jugadores!$B:$B,$C3)) -> #REF! | G3: =IF($C3="","",SUMIFS(Resultats_jugadores!$D:$D,Resultats_jugadores!$A:$A,$A3,Resultats_jugadores!$B:$B,$C3)) -> #REF! | H3: =IF($C3="","",N($F3)-N($G3)) -> #REF! | I3: {=IF($C3="","",IFERROR(INDEX(Partits!$C:$C,MATCH($A3&"_"&$D3,Partits!$D:$D,0)),""))} -> #REF! | J3: =IF($C3="","",IF(AND($I3="V",N($H3)>0),1.2,1)) -> #REF! | K3: =IF($C3="","",N($H3)*$J3) -> #REF! | L3: =IF($C3="","",IF($E3="SI",2,1)) -> #REF! | M3: =IF($C3="","",$K3*$L3) -> #REF!
A4: =IF(#REF!="","",#REF!) -> #REF! | B4: =IF(#REF!="","",#REF!) -> #REF! | C4: =IF(#REF!="","",#REF!) -> #REF! | D4: =IF(#REF!="","",#REF!) -> #REF! | E4: =IF(#REF!="","",#REF!) -> #REF! | F4: =IF($C4="","",SUMIFS(Resultats_jugadores!$C:$C,Resultats_jugadores!$A:$A,$A4,Resultats_jugadores!$B:$B,$C4)) -> #REF! | G4: =IF($C4="","",SUMIFS(Resultats_jugadores!$D:$D,Resultats_jugadores!$A:$A,$A4,Resultats_jugadores!$B:$B,$C4)) -> #REF! | H4: =IF($C4="","",N($F4)-N($G4)) -> #REF! | I4: {=IF($C4="","",IFERROR(INDEX(Partits!$C:$C,MATCH($A4&"_"&$D4,Partits!$D:$D,0)),""))} -> #REF! | J4: =IF($C4="","",IF(AND($I4="V",N($H4)>0),1.2,1)) -> #REF! | K4: =IF($C4="","",N($H4)*$J4) -> #REF! | L4: =IF($C4="","",IF($E4="SI",2,1)) -> #REF! | M4: =IF($C4="","",$K4*$L4) -> #REF!
A5: =IF(#REF!="","",#REF!) -> #REF! | B5: =IF(#REF!="","",#REF!) -> #REF! | C5: =IF(#REF!="","",#REF!) -> #REF! | D5: =IF(#REF!="","",#REF!) -> #REF! | E5: =IF(#REF!="","",#REF!) -> #REF! | F5: =IF($C5="","",SUMIFS(Resultats_jugadores!$C:$C,Resultats_jugadores!$A:$A,$A5,Resultats_jugadores!$B:$B,$C5)) -> #REF! | G5: =IF($C5="","",SUMIFS(Resultats_jugadores!$D:$D,Resultats_jugadores!$A:$A,$A5,Resultats_jugadores!$B:$B,$C5)) -> #REF! | H5: =IF($C5="","",N($F5)-N($G5)) -> #REF! | I5: {=IF($C5="","",IFERROR(INDEX(Partits!$C:$C,MATCH($A5&"_"&$D5,Partits!$D:$D,0)),""))} -> #REF! | J5: =IF($C5="","",IF(AND($I5="V",N($H5)>0),1.2,1)) -> #REF! | K5: =IF($C5="","",N($H5)*$J5) -> #REF! | L5: =IF($C5="","",IF($E5="SI",2,1)) -> #REF! | M5: =IF($C5="","",$K5*$L5) -> #REF!
A6: =IF(#REF!="","",#REF!) -> #REF! | B6: =IF(#REF!="","",#REF!) -> #REF! | C6: =IF(#REF!="","",#REF!) -> #REF! | D6: =IF(#REF!="","",#REF!) -> #REF! | E6: =IF(#REF!="","",#REF!) -> #REF! | F6: =IF($C6="","",SUMIFS(Resultats_jugadores!$C:$C,Resultats_jugadores!$A:$A,$A6,Resultats_jugadores!$B:$B,$C6)) -> #REF! | G6: =IF($C6="","",SUMIFS(Resultats_jugadores!$D:$D,Resultats_jugadores!$A:$A,$A6,Resultats_jugadores!$B:$B,$C6)) -> #REF! | H6: =IF($C6="","",N($F6)-N($G6)) -> #REF! | I6: {=IF($C6="","",IFERROR(INDEX(Partits!$C:$C,MATCH($A6&"_"&$D6,Partits!$D:$D,0)),""))} -> #REF! | J6: =IF($C6="","",IF(AND($I6="V",N($H6)>0),1.2,1)) -> #REF! | K6: =IF($C6="","",N($H6)*$J6) -> #REF! | L6: =IF($C6="","",IF($E6="SI",2,1)) -> #REF! | M6: =IF($C6="","",$K6*$L6) -> #REF!
A7: =IF(#REF!="","",#REF!) -> #REF! | B7: =IF(#REF!="","",#REF!) -> #REF! | C7: =IF(#REF!="","",#REF!) -> #REF! | D7: =IF(#REF!="","",#REF!) -> #REF! | E7: =IF(#REF!="","",#REF!) -> #REF! | F7: =IF($C7="","",SUMIFS(Resultats_jugadores!$C:$C,Resultats_jugadores!$A:$A,$A7,Resultats_jugadores!$B:$B,$C7)) -> #REF! | G7: =IF($C7="","",SUMIFS(Resultats_jugadores!$D:$D,Resultats_jugadores!$A:$A,$A7,Resultats_jugadores!$B:$B,$C7)) -> #REF! | H7: =IF($C7="","",N($F7)-N($G7)) -> #REF! | I7: {=IF($C7="","",IFERROR(INDEX(Partits!$C:$C,MATCH($A7&"_"&$D7,Partits!$D:$D,0)),""))} -> #REF! | J7: =IF($C7="","",IF(AND($I7="V",N($H7)>0),1.2,1)) -> #REF! | K7: =IF($C7="","",N($H7)*$J7) -> #REF! | L7: =IF($C7="","",IF($E7="SI",2,1)) -> #REF! | M7: =IF($C7="","",$K7*$L7) -> #REF!
A8: =IF(#REF!="","",#REF!) -> #REF! | B8: =IF(#REF!="","",#REF!) -> #REF! | C8: =IF(#REF!="","",#REF!) -> #REF! | D8: =IF(#REF!="","",#REF!) -> #REF! | E8: =IF(#REF!="","",#REF!) -> #REF! | F8: =IF($C8="","",SUMIFS(Resultats_jugadores!$C:$C,Resultats_jugadores!$A:$A,$A8,Resultats_jugadores!$B:$B,$C8)) -> #REF! | G8: =IF($C8="","",SUMIFS(Resultats_jugadores!$D:$D,Resultats_jugadores!$A:$A,$A8,Resultats_jugadores!$B:$B,$C8)) -> #REF! | H8: =IF($C8="","",N($F8)-N($G8)) -> #REF! | I8: {=IF($C8="","",IFERROR(INDEX(Partits!$C:$C,MATCH($A8&"_"&$D8,Partits!$D:$D,0)),""))} -> #REF! | J8: =IF($C8="","",IF(AND($I8="V",N($H8)>0),1.2,1)) -> #REF! | K8: =IF($C8="","",N($H8)*$J8) -> #REF! | L8: =IF($C8="","",IF($E8="SI",2,1)) -> #REF! | M8: =IF($C8="","",$K8*$L8) -> #REF!
A9: =IF(#REF!="","",#REF!) -> #REF! | B9: =IF(#REF!="","",#REF!) -> #REF! | C9: =IF(#REF!="","",#REF!) -> #REF! | D9: =IF(#REF!="","",#REF!) -> #REF! | E9: =IF(#REF!="","",#REF!) -> #REF! | F9: =IF($C9="","",SUMIFS(Resultats_jugadores!$C:$C,Resultats_jugadores!$A:$A,$A9,Resultats_jugadores!$B:$B,$C9)) -> #REF! | G9: =IF($C9="","",SUMIFS(Resultats_jugadores!$D:$D,Resultats_jugadores!$A:$A,$A9,Resultats_jugadores!$B:$B,$C9)) -> #REF! | H9: =IF($C9="","",N($F9)-N($G9)) -> #REF! | I9: {=IF($C9="","",IFERROR(INDEX(Partits!$C:$C,MATCH($A9&"_"&$D9,Partits!$D:$D,0)),""))} -> #REF! | J9: =IF($C9="","",IF(AND($I9="V",N($H9)>0),1.2,1)) -> #REF! | K9: =IF($C9="","",N($H9)*$J9) -> #REF! | L9: =IF($C9="","",IF($E9="SI",2,1)) -> #REF! | M9: =IF($C9="","",$K9*$L9) -> #REF!
A10: =IF(#REF!="","",#REF!) -> #REF! | B10: =IF(#REF!="","",#REF!) -> #REF! | C10: =IF(#REF!="","",#REF!) -> #REF! | D10: =IF(#REF!="","",#REF!) -> #REF! | E10: =IF(#REF!="","",#REF!) -> #REF! | F10: =IF($C10="","",SUMIFS(Resultats_jugadores!$C:$C,Resultats_jugadores!$A:$A,$A10,Resultats_jugadores!$B:$B,$C10)) -> #REF! | G10: =IF($C10="","",SUMIFS(Resultats_jugadores!$D:$D,Resultats_jugadores!$A:$A,$A10,Resultats_jugadores!$B:$B,$C10)) -> #REF! | H10: =IF($C10="","",N($F10)-N($G10)) -> #REF! | I10: {=IF($C10="","",IFERROR(INDEX(Partits!$C:$C,MATCH($A10&"_"&$D10,Partits!$D:$D,0)),""))} -> #REF! | J10: =IF($C10="","",IF(AND($I10="V",N($H10)>0),1.2,1)) -> #REF! | K10: =IF($C10="","",N($H10)*$J10) -> #REF! | L10: =IF($C10="","",IF($E10="SI",2,1)) -> #REF! | M10: =IF($C10="","",$K10*$L10) -> #REF!
A11: =IF(Equips_usuari!A11="","",Equips_usuari!A11) -> 1 | B11: =IF(Equips_usuari!B11="","",Equips_usuari!B11) -> U17+SFB | C11: =IF(Equips_usuari!C11="","",Equips_usuari!C11) -> Nina Clotet | D11: =IF(Equips_usuari!D11="","",Equips_usuari!D11) -> U16 | E11: =IF(Equips_usuari!F11="","",Equips_usuari!F11) -> NO | F11: =IF($C11="","",SUMIFS(Resultats_jugadores!$C:$C,Resultats_jugadores!$A:$A,$A11,Resultats_jugadores!$B:$B,$C11)) -> 0 | G11: =IF($C11="","",SUMIFS(Resultats_jugadores!$D:$D,Resultats_jugadores!$A:$A,$A11,Resultats_jugadores!$B:$B,$C11)) -> 0 | H11: =IF($C11="","",N($F11)-N($G11)) -> 0 | I11: {=IF($C11="","",IFERROR(INDEX(Partits!$C:$C,MATCH($A11&"_"&$D11,Partits!$D:$D,0)),""))} -> V | J11: =IF($C11="","",IF(AND($I11="V",N($H11)>0),1.2,1)) -> 1 | K11: =IF($C11="","",N($H11)*$J11) -> 0 | L11: =IF($C11="","",IF($E11="SI",2,1)) -> 1 | M11: =IF($C11="","",$K11*$L11) -> 0
A12: =IF(Equips_usuari!A12="","",Equips_usuari!A12) -> 1 | B12: =IF(Equips_usuari!B12="","",Equips_usuari!B12) -> U17+SFB | C12: =IF(Equips_usuari!C12="","",Equips_usuari!C12) -> Erica Farizo | D12: =IF(Equips_usuari!D12="","",Equips_usuari!D12) -> U15 | E12: =IF(Equips_usuari!F12="","",Equips_usuari!F12) -> NO | F12: =IF($C12="","",SUMIFS(Resultats_jugadores!$C:$C,Resultats_jugadores!$A:$A,$A12,Resultats_jugadores!$B:$B,$C12)) -> 0 | G12: =IF($C12="","",SUMIFS(Resultats_jugadores!$D:$D,Resultats_jugadores!$A:$A,$A12,Resultats_jugadores!$B:$B,$C12)) -> 0 | H12: =IF($C12="","",N($F12)-N($G12)) -> 0 | I12: {=IF($C12="","",IFERROR(INDEX(Partits!$C:$C,MATCH($A12&"_"&$D12,Partits!$D:$D,0)),""))} -> V | J12: =IF($C12="","",IF(AND($I12="V",N($H12)>0),1.2,1)) -> 1 | K12: =IF($C12="","",N($H12)*$J12) -> 0 | L12: =IF($C12="","",IF($E12="SI",2,1)) -> 1 | M12: =IF($C12="","",$K12*$L12) -> 0
A13: =IF(Equips_usuari!A13="","",Equips_usuari!A13) -> 1 | B13: =IF(Equips_usuari!B13="","",Equips_usuari!B13) -> U17+SFB | C13: =IF(Equips_usuari!C13="","",Equips_usuari!C13) -> Marina Melero | D13: =IF(Equips_usuari!D13="","",Equips_usuari!D13) -> LF2 | E13: =IF(Equips_usuari!F13="","",Equips_usuari!F13) -> SI | F13: =IF($C13="","",SUMIFS(Resultats_jugadores!$C:$C,Resultats_jugadores!$A:$A,$A13,Resultats_jugadores!$B:$B,$C13)) -> 16 | G13: =IF($C13="","",SUMIFS(Resultats_jugadores!$D:$D,Resultats_jugadores!$A:$A,$A13,Resultats_jugadores!$B:$B,$C13)) -> 3 | H13: =IF($C13="","",N($F13)-N($G13)) -> 13 | I13: {=IF($C13="","",IFERROR(INDEX(Partits!$C:$C,MATCH($A13&"_"&$D13,Partits!$D:$D,0)),""))} -> V | J13: =IF($C13="","",IF(AND($I13="V",N($H13)>0),1.2,1)) -> 1.2 | K13: =IF($C13="","",N($H13)*$J13) -> 15.6 | L13: =IF($C13="","",IF($E13="SI",2,1)) -> 2 | M13: =IF($C13="","",$K13*$L13) -> 31.2
A14: =IF(Equips_usuari!A14="","",Equips_usuari!A14) -> 1 | B14: =IF(Equips_usuari!B14="","",Equips_usuari!B14) -> U17+SFB | C14: =IF(Equips_usuari!C14="","",Equips_usuari!C14) -> Carla Tabares | D14: =IF(Equips_usuari!D14="","",Equips_usuari!D14) -> U17 | E14: =IF(Equips_usuari!F14="","",Equips_usuari!F14) -> NO | F14: =IF($C14="","",SUMIFS(Resultats_jugadores!$C:$C,Resultats_jugadores!$A:$A,$A14,Resultats_jugadores!$B:$B,$C14)) -> 0 | G14: =IF($C14="","",SUMIFS(Resultats_jugadores!$D:$D,Resultats_jugadores!$A:$A,$A14,Resultats_jugadores!$B:$B,$C14)) -> 0 | H14: =IF($C14="","",N($F14)-N($G14)) -> 0 | I14: {=IF($C14="","",IFERROR(INDEX(Partits!$C:$C,MATCH($A14&"_"&$D14,Partits!$D:$D,0)),""))} -> V | J14: =IF($C14="","",IF(AND($I14="V",N($H14)>0),1.2,1)) -> 1 | K14: =IF($C14="","",N($H14)*$J14) -> 0 | L14: =IF($C14="","",IF($E14="SI",2,1)) -> 1 | M14: =IF($C14="","",$K14*$L14) -> 0
A15: =IF(Equips_usuari!A15="","",Equips_usuari!A15) -> 1 | B15: =IF(Equips_usuari!B15="","",Equips_usuari!B15) -> U17+SFB | C15: =IF(Equips_usuari!C15="","",Equips_usuari!C15) -> Júlia Arcos | D15: =IF(Equips_usuari!D15="","",Equips_usuari!D15) -> U18 | E15: =IF(Equips_usuari!F15="","",Equips_usuari!F15) -> NO | F15: =IF($C15="","",SUMIFS(Resultats_jugadores!$C:$C,Resultats_jugadores!$A:$A,$A15,Resultats_jugadores!$B:$B,$C15)) -> 8 | G15: =IF($C15="","",SUMIFS(Resultats_jugadores!$D:$D,Resultats_jugadores!$A:$A,$A15,Resultats_jugadores!$B:$B,$C15)) -> 2 | H15: =IF($C15="","",N($F15)-N($G15)) -> 6 | I15: {=IF($C15="","",IFERROR(INDEX(Partits!$C:$C,MATCH($A15&"_"&$D15,Partits!$D:$D,0)),""))} -> V | J15: =IF($C15="","",IF(AND($I15="V",N($H15)>0),1.2,1)) -> 1.2 | K15: =IF($C15="","",N($H15)*$J15) -> 7.2 | L15: =IF($C15="","",IF($E15="SI",2,1)) -> 1 | M15: =IF($C15="","",$K15*$L15) -> 7.2
A16: =IF(Equips_usuari!A16="","",Equips_usuari!A16) -> 1 | B16: =IF(Equips_usuari!B16="","",Equips_usuari!B16) -> U17+SFB | C16: =IF(Equips_usuari!C16="","",Equips_usuari!C16) -> Abril Pérez | D16: =IF(Equips_usuari!D16="","",Equips_usuari!D16) -> U15 | E16: =IF(Equips_usuari!F16="","",Equips_usuari!F16) -> NO | F16: =IF($C16="","",SUMIFS(Resultats_jugadores!$C:$C,Resultats_jugadores!$A:$A,$A16,Resultats_jugadores!$B:$B,$C16)) -> 0 | G16: =IF($C16="","",SUMIFS(Resultats_jugadores!$D:$D,Resultats_jugadores!$A:$A,$A16,Resultats_jugadores!$B:$B,$C16)) -> 0 | H16: =IF($C16="","",N($F16)-N($G16)) -> 0 | I16: {=IF($C16="","",IFERROR(INDEX(Partits!$C:$C,MATCH($A16&"_"&$D16,Partits!$D:$D,0)),""))} -> V | J16: =IF($C16="","",IF(AND($I16="V",N($H16)>0),1.2,1)) -> 1 | K16: =IF($C16="","",N($H16)*$J16) -> 0 | L16: =IF($C16="","",IF($E16="SI",2,1)) -> 1 | M16: =IF($C16="","",$K16*$L16) -> 0
A17: =IF(Equips_usuari!A17="","",Equips_usuari!A17) -> 1 | B17: =IF(Equips_usuari!B17="","",Equips_usuari!B17) -> U17+SFB | C17: =IF(Equips_usuari!C17="","",Equips_usuari!C17) -> Aina Torras | D17: =IF(Equips_usuari!D17="","",Equips_usuari!D17) -> U13 | E17: =IF(Equips_usuari!F17="","",Equips_usuari!F17) -> NO | F17: =IF($C17="","",SUMIFS(Resultats_jugadores!$C:$C,Resultats_jugadores!$A:$A,$A17,Resultats_jugadores!$B:$B,$C17)) -> 2 | G17: =IF($C17="","",SUMIFS(Resultats_jugadores!$D:$D,Resultats_jugadores!$A:$A,$A17,Resultats_jugadores!$B:$B,$C17)) -> 1 | H17: =IF($C17="","",N($F17)-N($G17)) -> 1 | I17: {=IF($C17="","",IFERROR(INDEX(Partits!$C:$C,MATCH($A17&"_"&$D17,Partits!$D:$D,0)),""))} -> V | J17: =IF($C17="","",IF(AND($I17="V",N($H17)>0),1.2,1)) -> 1.2 | K17: =IF($C17="","",N($H17)*$J17) -> 1.2 | L17: =IF($C17="","",IF($E17="SI",2,1)) -> 1 | M17: =IF($C17="","",$K17*$L17) -> 1.2
A18: =IF(Equips_usuari!A18="","",Equips_usuari!A18) -> 1 | B18: =IF(Equips_usuari!B18="","",Equips_usuari!B18) -> U17+SFB | C18: =IF(Equips_usuari!C18="","",Equips_usuari!C18) -> Laia Muncunill | D18: =IF(Equips_usuari!D18="","",Equips_usuari!D18) -> U16 | E18: =IF(Equips_usuari!F18="","",Equips_usuari!F18) -> NO | F18: =IF($C18="","",SUMIFS(Resultats_jugadores!$C:$C,Resultats_jugadores!$A:$A,$A18,Resultats_jugadores!$B:$B,$C18)) -> 0 | G18: =IF($C18="","",SUMIFS(Resultats_jugadores!$D:$D,Resultats_jugadores!$A:$A,$A18,Resultats_jugadores!$B:$B,$C18)) -> 0 | H18: =IF($C18="","",N($F18)-N($G18)) -> 0 | I18: {=IF($C18="","",IFERROR(INDEX(Partits!$C:$C,MATCH($A18&"_"&$D18,Partits!$D:$D,0)),""))} -> V | J18: =IF($C18="","",IF(AND($I18="V",N($H18)>0),1.2,1)) -> 1 | K18: =IF($C18="","",N($H18)*$J18) -> 0 | L18: =IF($C18="","",IF($E18="SI",2,1)) -> 1 | M18: =IF($C18="","",$K18*$L18) -> 0
A19: =IF(Equips_usuari!A19="","",Equips_usuari!A19) -> 1 | B19: =IF(Equips_usuari!B19="","",Equips_usuari!B19) -> U17+SFB | C19: =IF(Equips_usuari!C19="","",Equips_usuari!C19) -> Mbakourou Dembele | D19: =IF(Equips_usuari!D19="","",Equips_usuari!D19) -> U18 | E19: =IF(Equips_usuari!F19="","",Equips_usuari!F19) -> NO | F19: =IF($C19="","",SUMIFS(Resultats_jugadores!$C:$C,Resultats_jugadores!$A:$A,$A19,Resultats_jugadores!$B:$B,$C19)) -> 7 | G19: =IF($C19="","",SUMIFS(Resultats_jugadores!$D:$D,Resultats_jugadores!$A:$A,$A19,Resultats_jugadores!$B:$B,$C19)) -> 3 | H19: =IF($C19="","",N($F19)-N($G19)) -> 4 | I19: {=IF($C19="","",IFERROR(INDEX(Partits!$C:$C,MATCH($A19&"_"&$D19,Partits!$D:$D,0)),""))} -> V | J19: =IF($C19="","",IF(AND($I19="V",N($H19)>0),1.2,1)) -> 1.2 | K19: =IF($C19="","",N($H19)*$J19) -> 4.8 | L19: =IF($C19="","",IF($E19="SI",2,1)) -> 1 | M19: =IF($C19="","",$K19*$L19) -> 4.8
A20: =IF(Equips_usuari!A2="","",Equips_usuari!A2) -> 1 | B20: =IF(Equips_usuari!B2="","",Equips_usuari!B2) -> U15 | C20: =IF(Equips_usuari!C2="","",Equips_usuari!C2) -> Marina Melero | D20: =IF(Equips_usuari!D2="","",Equips_usuari!D2) -> LF2 | E20: =IF(Equips_usuari!F2="","",Equips_usuari!F2) -> NO | F20: =IF($C20="","",SUMIFS(Resultats_jugadores!$C:$C,Resultats_jugadores!$A:$A,$A20,Resultats_jugadores!$B:$B,$C20)) -> 16 | G20: =IF($C20="","",SUMIFS(Resultats_jugadores!$D:$D,Resultats_jugadores!$A:$A,$A20,Resultats_jugadores!$B:$B,$C20)) -> 3 | H20: =IF($C20="","",N($F20)-N($G20)) -> 13 | I20: {=IF($C20="","",IFERROR(INDEX(Partits!$C:$C,MATCH($A20&"_"&$D20,Partits!$D:$D,0)),""))} -> V | J20: =IF($C20="","",IF(AND($I20="V",N($H20)>0),1.2,1)) -> 1.2 | K20: =IF($C20="","",N($H20)*$J20) -> 15.6 | L20: =IF($C20="","",IF($E20="SI",2,1)) -> 1 | M20: =IF($C20="","",$K20*$L20) -> 15.6
A21: =IF(Equips_usuari!A3="","",Equips_usuari!A3) -> 1 | B21: =IF(Equips_usuari!B3="","",Equips_usuari!B3) -> U15 | C21: =IF(Equips_usuari!C3="","",Equips_usuari!C3) -> Martina Agramunt | D21: =IF(Equips_usuari!D3="","",Equips_usuari!D3) -> U13 | E21: =IF(Equips_usuari!F3="","",Equips_usuari!F3) -> NO | F21: =IF($C21="","",SUMIFS(Resultats_jugadores!$C:$C,Resultats_jugadores!$A:$A,$A21,Resultats_jugadores!$B:$B,$C21)) -> 16 | G21: =IF($C21="","",SUMIFS(Resultats_jugadores!$D:$D,Resultats_jugadores!$A:$A,$A21,Resultats_jugadores!$B:$B,$C21)) -> 1 | H21: =IF($C21="","",N($F21)-N($G21)) -> 15 | I21: {=IF($C21="","",IFERROR(INDEX(Partits!$C:$C,MATCH($A21&"_"&$D21,Partits!$D:$D,0)),""))} -> V | J21: =IF($C21="","",IF(AND($I21="V",N($H21)>0),1.2,1)) -> 1.2 | K21: =IF($C21="","",N($H21)*$J21) -> 18 | L21: =IF($C21="","",IF($E21="SI",2,1)) -> 1 | M21: =IF($C21="","",$K21*$L21) -> 18
A22: =IF(Equips_usuari!A4="","",Equips_usuari!A4) -> 1 | B22: =IF(Equips_usuari!B4="","",Equips_usuari!B4) -> U15 | C22: =IF(Equips_usuari!C4="","",Equips_usuari!C4) -> Kourafy Dembele | D22: =IF(Equips_usuari!D4="","",Equips_usuari!D4) -> U18 | E22: =IF(Equips_usuari!F4="","",Equips_usuari!F4) -> NO | F22: =IF($C22="","",SUMIFS(Resultats_jugadores!$C:$C,Resultats_jugadores!$A:$A,$A22,Resultats_jugadores!$B:$B,$C22)) -> 10 | G22: =IF($C22="","",SUMIFS(Resultats_jugadores!$D:$D,Resultats_jugadores!$A:$A,$A22,Resultats_jugadores!$B:$B,$C22)) -> 2 | H22: =IF($C22="","",N($F22)-N($G22)) -> 8 | I22: {=IF($C22="","",IFERROR(INDEX(Partits!$C:$C,MATCH($A22&"_"&$D22,Partits!$D:$D,0)),""))} -> V | J22: =IF($C22="","",IF(AND($I22="V",N($H22)>0),1.2,1)) -> 1.2 | K22: =IF($C22="","",N($H22)*$J22) -> 9.6 | L22: =IF($C22="","",IF($E22="SI",2,1)) -> 1 | M22: =IF($C22="","",$K22*$L22) -> 9.6
A23: =IF(Equips_usuari!A5="","",Equips_usuari!A5) -> 1 | B23: =IF(Equips_usuari!B5="","",Equips_usuari!B5) -> U15 | C23: =IF(Equips_usuari!C5="","",Equips_usuari!C5) -> Clàudia Barcons | D23: =IF(Equips_usuari!D5="","",Equips_usuari!D5) -> U13 | E23: =IF(Equips_usuari!F5="","",Equips_usuari!F5) -> NO | F23: =IF($C23="","",SUMIFS(Resultats_jugadores!$C:$C,Resultats_jugadores!$A:$A,$A23,Resultats_jugadores!$B:$B,$C23)) -> 5 | G23: =IF($C23="","",SUMIFS(Resultats_jugadores!$D:$D,Resultats_jugadores!$A:$A,$A23,Resultats_jugadores!$B:$B,$C23)) -> 4 | H23: =IF($C23="","",N($F23)-N($G23)) -> 1 | I23: {=IF($C23="","",IFERROR(INDEX(Partits!$C:$C,MATCH($A23&"_"&$D23,Partits!$D:$D,0)),""))} -> V | J23: =IF($C23="","",IF(AND($I23="V",N($H23)>0),1.2,1)) -> 1.2 | K23: =IF($C23="","",N($H23)*$J23) -> 1.2 | L23: =IF($C23="","",IF($E23="SI",2,1)) -> 1 | M23: =IF($C23="","",$K23*$L23) -> 1.2
A24: =IF(Equips_usuari!A6="","",Equips_usuari!A6) -> 1 | B24: =IF(Equips_usuari!B6="","",Equips_usuari!B6) -> U15 | C24: =IF(Equips_usuari!C6="","",Equips_usuari!C6) -> Eulàlia Mayor | D24: =IF(Equips_usuari!D6="","",Equips_usuari!D6) -> U16 | E24: =IF(Equips_usuari!F6="","",Equips_usuari!F6) -> NO | F24: =IF($C24="","",SUMIFS(Resultats_jugadores!$C:$C,Resultats_jugadores!$A:$A,$A24,Resultats_jugadores!$B:$B,$C24)) -> 0 | G24: =IF($C24="","",SUMIFS(Resultats_jugadores!$D:$D,Resultats_jugadores!$A:$A,$A24,Resultats_jugadores!$B:$B,$C24)) -> 0 | H24: =IF($C24="","",N($F24)-N($G24)) -> 0 | I24: {=IF($C24="","",IFERROR(INDEX(Partits!$C:$C,MATCH($A24&"_"&$D24,Partits!$D:$D,0)),""))} -> V | J24: =IF($C24="","",IF(AND($I24="V",N($H24)>0),1.2,1)) -> 1 | K24: =IF($C24="","",N($H24)*$J24) -> 0 | L24: =IF($C24="","",IF($E24="SI",2,1)) -> 1 | M24: =IF($C24="","",$K24*$L24) -> 0
A25: =IF(Equips_usuari!A7="","",Equips_usuari!A7) -> 1 | B25: =IF(Equips_usuari!B7="","",Equips_usuari!B7) -> U15 | C25: =IF(Equips_usuari!C7="","",Equips_usuari!C7) -> Xènia Fígols | D25: =IF(Equips_usuari!D7="","",Equips_usuari!D7) -> U18 | E25: =IF(Equips_usuari!F7="","",Equips_usuari!F7) -> NO | F25: =IF($C25="","",SUMIFS(Resultats_jugadores!$C:$C,Resultats_jugadores!$A:$A,$A25,Resultats_jugadores!$B:$B,$C25)) -> 24 | G25: =IF($C25="","",SUMIFS(Resultats_jugadores!$D:$D,Resultats_jugadores!$A:$A,$A25,Resultats_jugadores!$B:$B,$C25)) -> 2 | H25: =IF($C25="","",N($F25)-N($G25)) -> 22 | I25: {=IF($C25="","",IFERROR(INDEX(Partits!$C:$C,MATCH($A25&"_"&$D25,Partits!$D:$D,0)),""))} -> V | J25: =IF($C25="","",IF(AND($I25="V",N($H25)>0),1.2,1)) -> 1.2 | K25: =IF($C25="","",N($H25)*$J25) -> 26.4 | L25: =IF($C25="","",IF($E25="SI",2,1)) -> 1 | M25: =IF($C25="","",$K25*$L25) -> 26.4
A26: =IF(Equips_usuari!A8="","",Equips_usuari!A8) -> 1 | B26: =IF(Equips_usuari!B8="","",Equips_usuari!B8) -> U15 | C26: =IF(Equips_usuari!C8="","",Equips_usuari!C8) -> Aina Torras | D26: =IF(Equips_usuari!D8="","",Equips_usuari!D8) -> U13 | E26: =IF(Equips_usuari!F8="","",Equips_usuari!F8) -> SI | F26: =IF($C26="","",SUMIFS(Resultats_jugadores!$C:$C,Resultats_jugadores!$A:$A,$A26,Resultats_jugadores!$B:$B,$C26)) -> 2 | G26: =IF($C26="","",SUMIFS(Resultats_jugadores!$D:$D,Resultats_jugadores!$A:$A,$A26,Resultats_jugadores!$B:$B,$C26)) -> 1 | H26: =IF($C26="","",N($F26)-N($G26)) -> 1 | I26: {=IF($C26="","",IFERROR(INDEX(Partits!$C:$C,MATCH($A26&"_"&$D26,Partits!$D:$D,0)),""))} -> V | J26: =IF($C26="","",IF(AND($I26="V",N($H26)>0),1.2,1)) -> 1.2 | K26: =IF($C26="","",N($H26)*$J26) -> 1.2 | L26: =IF($C26="","",IF($E26="SI",2,1)) -> 2 | M26: =IF($C26="","",$K26*$L26) -> 2.4
A27: =IF(Equips_usuari!A9="","",Equips_usuari!A9) -> 1 | B27: =IF(Equips_usuari!B9="","",Equips_usuari!B9) -> U15 | C27: =IF(Equips_usuari!C9="","",Equips_usuari!C9) -> Leyre Castelló | D27: =IF(Equips_usuari!D9="","",Equips_usuari!D9) -> U15 | E27: =IF(Equips_usuari!F9="","",Equips_usuari!F9) -> NO | F27: =IF($C27="","",SUMIFS(Resultats_jugadores!$C:$C,Resultats_jugadores!$A:$A,$A27,Resultats_jugadores!$B:$B,$C27)) -> 0 | G27: =IF($C27="","",SUMIFS(Resultats_jugadores!$D:$D,Resultats_jugadores!$A:$A,$A27,Resultats_jugadores!$B:$B,$C27)) -> 0 | H27: =IF($C27="","",N($F27)-N($G27)) -> 0 | I27: {=IF($C27="","",IFERROR(INDEX(Partits!$C:$C,MATCH($A27&"_"&$D27,Partits!$D:$D,0)),""))} -> V | J27: =IF($C27="","",IF(AND($I27="V",N($H27)>0),1.2,1)) -> 1 | K27: =IF($C27="","",N($H27)*$J27) -> 0 | L27: =IF($C27="","",IF($E27="SI",2,1)) -> 1 | M27: =IF($C27="","",$K27*$L27) -> 0
A28: =IF(Equips_usuari!A10="","",Equips_usuari!A10) -> 1 | B28: =IF(Equips_usuari!B10="","",Equips_usuari!B10) -> U15 | C28: =IF(Equips_usuari!C10="","",Equips_usuari!C10) -> Laia Muncunill | D28: =IF(Equips_usuari!D10="","",Equips_usuari!D10) -> U17 | E28: =IF(Equips_usuari!F10="","",Equips_usuari!F10) -> NO | F28: =IF($C28="","",SUMIFS(Resultats_jugadores!$C:$C,Resultats_jugadores!$A:$A,$A28,Resultats_jugadores!$B:$B,$C28)) -> 0 | G28: =IF($C28="","",SUMIFS(Resultats_jugadores!$D:$D,Resultats_jugadores!$A:$A,$A28,Resultats_jugadores!$B:$B,$C28)) -> 0 | H28: =IF($C28="","",N($F28)-N($G28)) -> 0 | I28: {=IF($C28="","",IFERROR(INDEX(Partits!$C:$C,MATCH($A28&"_"&$D28,Partits!$D:$D,0)),""))} -> V | J28: =IF($C28="","",IF(AND($I28="V",N($H28)>0),1.2,1)) -> 1 | K28: =IF($C28="","",N($H28)*$J28) -> 0 | L28: =IF($C28="","",IF($E28="SI",2,1)) -> 1 | M28: =IF($C28="","",$K28*$L28) -> 0
A29: =IF(Equips_usuari!A29="","",Equips_usuari!A29) -> 1 | B29: =IF(Equips_usuari!B29="","",Equips_usuari!B29) -> U14 | C29: =IF(Equips_usuari!C29="","",Equips_usuari!C29) -> Marina Melero | D29: =IF(Equips_usuari!D29="","",Equips_usuari!D29) -> LF2 | E29: =IF(Equips_usuari!F29="","",Equips_usuari!F29) -> SI | F29: =IF($C29="","",SUMIFS(Resultats_jugadores!$C:$C,Resultats_jugadores!$A:$A,$A29,Resultats_jugadores!$B:$B,$C29)) -> 16 | G29: =IF($C29="","",SUMIFS(Resultats_jugadores!$D:$D,Resultats_jugadores!$A:$A,$A29,Resultats_jugadores!$B:$B,$C29)) -> 3 | H29: =IF($C29="","",N($F29)-N($G29)) -> 13 | I29: {=IF($C29="","",IFERROR(INDEX(Partits!$C:$C,MATCH($A29&"_"&$D29,Partits!$D:$D,0)),""))} -> V | J29: =IF($C29="","",IF(AND($I29="V",N($H29)>0),1.2,1)) -> 1.2 | K29: =IF($C29="","",N($H29)*$J29) -> 15.6 | L29: =IF($C29="","",IF($E29="SI",2,1)) -> 2 | M29: =IF($C29="","",$K29*$L29) -> 31.2
A30: =IF(Equips_usuari!A30="","",Equips_usuari!A30) -> 1 | B30: =IF(Equips_usuari!B30="","",Equips_usuari!B30) -> U14 | C30: =IF(Equips_usuari!C30="","",Equips_usuari!C30) -> Martina Agramunt | D30: =IF(Equips_usuari!D30="","",Equips_usuari!D30) -> U13 | E30: =IF(Equips_usuari!F30="","",Equips_usuari!F30) -> NO | F30: =IF($C30="","",SUMIFS(Resultats_jugadores!$C:$C,Resultats_jugadores!$A:$A,$A30,Resultats_jugadores!$B:$B,$C30)) -> 16 | G30: =IF($C30="","",SUMIFS(Resultats_jugadores!$D:$D,Resultats_jugadores!$A:$A,$A30,Resultats_jugadores!$B:$B,$C30)) -> 1 | H30: =IF($C30="","",N($F30)-N($G30)) -> 15 | I30: {=IF($C30="","",IFERROR(INDEX(Partits!$C:$C,MATCH($A30&"_"&$D30,Partits!$D:$D,0)),""))} -> V | J30: =IF($C30="","",IF(AND($I30="V",N($H30)>0),1.2,1)) -> 1.2 | K30: =IF($C30="","",N($H30)*$J30) -> 18 | L30: =IF($C30="","",IF($E30="SI",2,1)) -> 1 | M30: =IF($C30="","",$K30*$L30) -> 18
A31: =IF(Equips_usuari!A31="","",Equips_usuari!A31) -> 1 | B31: =IF(Equips_usuari!B31="","",Equips_usuari!B31) -> U14 | C31: =IF(Equips_usuari!C31="","",Equips_usuari!C31) -> Nina Clotet | D31: =IF(Equips_usuari!D31="","",Equips_usuari!D31) -> U17 | E31: =IF(Equips_usuari!F31="","",Equips_usuari!F31) -> NO | F31: =IF($C31="","",SUMIFS(Resultats_jugadores!$C:$C,Resultats_jugadores!$A:$A,$A31,Resultats_jugadores!$B:$B,$C31)) -> 0 | G31: =IF($C31="","",SUMIFS(Resultats_jugadores!$D:$D,Resultats_jugadores!$A:$A,$A31,Resultats_jugadores!$B:$B,$C31)) -> 0 | H31: =IF($C31="","",N($F31)-N($G31)) -> 0 | I31: {=IF($C31="","",IFERROR(INDEX(Partits!$C:$C,MATCH($A31&"_"&$D31,Partits!$D:$D,0)),""))} -> V | J31: =IF($C31="","",IF(AND($I31="V",N($H31)>0),1.2,1)) -> 1 | K31: =IF($C31="","",N($H31)*$J31) -> 0 | L31: =IF($C31="","",IF($E31="SI",2,1)) -> 1 | M31: =IF($C31="","",$K31*$L31) -> 0
A32: =IF(Equips_usuari!A32="","",Equips_usuari!A32) -> 1 | B32: =IF(Equips_usuari!B32="","",Equips_usuari!B32) -> U14 | C32: =IF(Equips_usuari!C32="","",Equips_usuari!C32) -> Clàudia Fernández | D32: =IF(Equips_usuari!D32="","",Equips_usuari!D32) -> U17 | E32: =IF(Equips_usuari!F32="","",Equips_usuari!F32) -> NO | F32: =IF($C32="","",SUMIFS(Resultats_jugadores!$C:$C,Resultats_jugadores!$A:$A,$A32,Resultats_jugadores!$B:$B,$C32)) -> 0 | G32: =IF($C32="","",SUMIFS(Resultats_jugadores!$D:$D,Resultats_jugadores!$A:$A,$A32,Resultats_jugadores!$B:$B,$C32)) -> 0 | H32: =IF($C32="","",N($F32)-N($G32)) -> 0 | I32: {=IF($C32="","",IFERROR(INDEX(Partits!$C:$C,MATCH($A32&"_"&$D32,Partits!$D:$D,0)),""))} -> V | J32: =IF($C32="","",IF(AND($I32="V",N($H32)>0),1.2,1)) -> 1 | K32: =IF($C32="","",N($H32)*$J32) -> 0 | L32: =IF($C32="","",IF($E32="SI",2,1)) -> 1 | M32: =IF($C32="","",$K32*$L32) -> 0
A33: =IF(Equips_usuari!A33="","",Equips_usuari!A33) -> 1 | B33: =IF(Equips_usuari!B33="","",Equips_usuari!B33) -> U14 | C33: =IF(Equips_usuari!C33="","",Equips_usuari!C33) -> Xènia Fígols | D33: =IF(Equips_usuari!D33="","",Equips_usuari!D33) -> U18 | E33: =IF(Equips_usuari!F33="","",Equips_usuari!F33) -> NO | F33: =IF($C33="","",SUMIFS(Resultats_jugadores!$C:$C,Resultats_jugadores!$A:$A,$A33,Resultats_jugadores!$B:$B,$C33)) -> 24 | G33: =IF($C33="","",SUMIFS(Resultats_jugadores!$D:$D,Resultats_jugadores!$A:$A,$A33,Resultats_jugadores!$B:$B,$C33)) -> 2 | H33: =IF($C33="","",N($F33)-N($G33)) -> 22 | I33: {=IF($C33="","",IFERROR(INDEX(Partits!$C:$C,MATCH($A33&"_"&$D33,Partits!$D:$D,0)),""))} -> V | J33: =IF($C33="","",IF(AND($I33="V",N($H33)>0),1.2,1)) -> 1.2 | K33: =IF($C33="","",N($H33)*$J33) -> 26.4 | L33: =IF($C33="","",IF($E33="SI",2,1)) -> 1 | M33: =IF($C33="","",$K33*$L33) -> 26.4
A34: =IF(Equips_usuari!A34="","",Equips_usuari!A34) -> 1 | B34: =IF(Equips_usuari!B34="","",Equips_usuari!B34) -> U14 | C34: =IF(Equips_usuari!C34="","",Equips_usuari!C34) -> Júlia Arcos | D34: =IF(Equips_usuari!D34="","",Equips_usuari!D34) -> U18 | E34: =IF(Equips_usuari!F34="","",Equips_usuari!F34) -> NO | F34: =IF($C34="","",SUMIFS(Resultats_jugadores!$C:$C,Resultats_jugadores!$A:$A,$A34,Resultats_jugadores!$B:$B,$C34)) -> 8 | G34: =IF($C34="","",SUMIFS(Resultats_jugadores!$D:$D,Resultats_jugadores!$A:$A,$A34,Resultats_jugadores!$B:$B,$C34)) -> 2 | H34: =IF($C34="","",N($F34)-N($G34)) -> 6 | I34: {=IF($C34="","",IFERROR(INDEX(Partits!$C:$C,MATCH($A34&"_"&$D34,Partits!$D:$D,0)),""))} -> V | J34: =IF($C34="","",IF(AND($I34="V",N($H34)>0),1.2,1)) -> 1.2 | K34: =IF($C34="","",N($H34)*$J34) -> 7.2 | L34: =IF($C34="","",IF($E34="SI",2,1)) -> 1 | M34: =IF($C34="","",$K34*$L34) -> 7.2
A35: =IF(Equips_usuari!A35="","",Equips_usuari!A35) -> 1 | B35: =IF(Equips_usuari!B35="","",Equips_usuari!B35) -> U14 | C35: =IF(Equips_usuari!C35="","",Equips_usuari!C35) -> Aina Torras | D35: =IF(Equips_usuari!D35="","",Equips_usuari!D35) -> U13 | E35: =IF(Equips_usuari!F35="","",Equips_usuari!F35) -> NO | F35: =IF($C35="","",SUMIFS(Resultats_jugadores!$C:$C,Resultats_jugadores!$A:$A,$A35,Resultats_jugadores!$B:$B,$C35)) -> 2 | G35: =IF($C35="","",SUMIFS(Resultats_jugadores!$D:$D,Resultats_jugadores!$A:$A,$A35,Resultats_jugadores!$B:$B,$C35)) -> 1 | H35: =IF($C35="","",N($F35)-N($G35)) -> 1 | I35: {=IF($C35="","",IFERROR(INDEX(Partits!$C:$C,MATCH($A35&"_"&$D35,Partits!$D:$D,0)),""))} -> V | J35: =IF($C35="","",IF(AND($I35="V",N($H35)>0),1.2,1)) -> 1.2 | K35: =IF($C35="","",N($H35)*$J35) -> 1.2 | L35: =IF($C35="","",IF($E35="SI",2,1)) -> 1 | M35: =IF($C35="","",$K35*$L35) -> 1.2
A36: =IF(Equips_usuari!A36="","",Equips_usuari!A36) -> 1 | B36: =IF(Equips_usuari!B36="","",Equips_usuari!B36) -> U14 | C36: =IF(Equips_usuari!C36="","",Equips_usuari!C36) -> Laia Muncunill | D36: =IF(Equips_usuari!D36="","",Equips_usuari!D36) -> U16 | E36: =IF(Equips_usuari!F36="","",Equips_usuari!F36) -> NO | F36: =IF($C36="","",SUMIFS(Resultats_jugadores!$C:$C,Resultats_jugadores!$A:$A,$A36,Resultats_jugadores!$B:$B,$C36)) -> 0 | G36: =IF($C36="","",SUMIFS(Resultats_jugadores!$D:$D,Resultats_jugadores!$A:$A,$A36,Resultats_jugadores!$B:$B,$C36)) -> 0 | H36: =IF($C36="","",N($F36)-N($G36)) -> 0 | I36: {=IF($C36="","",IFERROR(INDEX(Partits!$C:$C,MATCH($A36&"_"&$D36,Partits!$D:$D,0)),""))} -> V | J36: =IF($C36="","",IF(AND($I36="V",N($H36)>0),1.2,1)) -> 1 | K36: =IF($C36="","",N($H36)*$J36) -> 0 | L36: =IF($C36="","",IF($E36="SI",2,1)) -> 1 | M36: =IF($C36="","",$K36*$L36) -> 0
A37: =IF(Equips_usuari!A37="","",Equips_usuari!A37) -> 1 | B37: =IF(Equips_usuari!B37="","",Equips_usuari!B37) -> U14 | C37: =IF(Equips_usuari!C37="","",Equips_usuari!C37) -> Leyre Castelló | D37: =IF(Equips_usuari!D37="","",Equips_usuari!D37) -> U15 | E37: =IF(Equips_usuari!F37="","",Equips_usuari!F37) -> NO | F37: =IF($C37="","",SUMIFS(Resultats_jugadores!$C:$C,Resultats_jugadores!$A:$A,$A37,Resultats_jugadores!$B:$B,$C37)) -> 0 | G37: =IF($C37="","",SUMIFS(Resultats_jugadores!$D:$D,Resultats_jugadores!$A:$A,$A37,Resultats_jugadores!$B:$B,$C37)) -> 0 | H37: =IF($C37="","",N($F37)-N($G37)) -> 0 | I37: {=IF($C37="","",IFERROR(INDEX(Partits!$C:$C,MATCH($A37&"_"&$D37,Partits!$D:$D,0)),""))} -> V | J37: =IF($C37="","",IF(AND($I37="V",N($H37)>0),1.2,1)) -> 1 | K37: =IF($C37="","",N($H37)*$J37) -> 0 | L37: =IF($C37="","",IF($E37="SI",2,1)) -> 1 | M37: =IF($C37="","",$K37*$L37) -> 0
A38: =IF(Equips_usuari!A38="","",Equips_usuari!A38) -> 1 | B38: =IF(Equips_usuari!B38="","",Equips_usuari!B38) -> LF2 | C38: =IF(Equips_usuari!C38="","",Equips_usuari!C38) -> Marina Melero | D38: =IF(Equips_usuari!D38="","",Equips_usuari!D38) -> LF2 | E38: =IF(Equips_usuari!F38="","",Equips_usuari!F38) -> NO | F38: =IF($C38="","",SUMIFS(Resultats_jugadores!$C:$C,Resultats_jugadores!$A:$A,$A38,Resultats_jugadores!$B:$B,$C38)) -> 16 | G38: =IF($C38="","",SUMIFS(Resultats_jugadores!$D:$D,Resultats_jugadores!$A:$A,$A38,Resultats_jugadores!$B:$B,$C38)) -> 3 | H38: =IF($C38="","",N($F38)-N($G38)) -> 13 | I38: {=IF($C38="","",IFERROR(INDEX(Partits!$C:$C,MATCH($A38&"_"&$D38,Partits!$D:$D,0)),""))} -> V | J38: =IF($C38="","",IF(AND($I38="V",N($H38)>0),1.2,1)) -> 1.2 | K38: =IF($C38="","",N($H38)*$J38) -> 15.6 | L38: =IF($C38="","",IF($E38="SI",2,1)) -> 1 | M38: =IF($C38="","",$K38*$L38) -> 15.6
A39: =IF(Equips_usuari!A39="","",Equips_usuari!A39) -> 1 | B39: =IF(Equips_usuari!B39="","",Equips_usuari!B39) -> LF2 | C39: =IF(Equips_usuari!C39="","",Equips_usuari!C39) -> Kourafy Dembele | D39: =IF(Equips_usuari!D39="","",Equips_usuari!D39) -> U18 | E39: =IF(Equips_usuari!F39="","",Equips_usuari!F39) -> NO | F39: =IF($C39="","",SUMIFS(Resultats_jugadores!$C:$C,Resultats_jugadores!$A:$A,$A39,Resultats_jugadores!$B:$B,$C39)) -> 10 | G39: =IF($C39="","",SUMIFS(Resultats_jugadores!$D:$D,Resultats_jugadores!$A:$A,$A39,Resultats_jugadores!$B:$B,$C39)) -> 2 | H39: =IF($C39="","",N($F39)-N($G39)) -> 8 | I39: {=IF($C39="","",IFERROR(INDEX(Partits!$C:$C,MATCH($A39&"_"&$D39,Partits!$D:$D,0)),""))} -> V | J39: =IF($C39="","",IF(AND($I39="V",N($H39)>0),1.2,1)) -> 1.2 | K39: =IF($C39="","",N($H39)*$J39) -> 9.6 | L39: =IF($C39="","",IF($E39="SI",2,1)) -> 1 | M39: =IF($C39="","",$K39*$L39) -> 9.6
A40: =IF(Equips_usuari!A40="","",Equips_usuari!A40) -> 1 | B40: =IF(Equips_usuari!B40="","",Equips_usuari!B40) -> LF2 | C40: =IF(Equips_usuari!C40="","",Equips_usuari!C40) -> Nina Clotet | D40: =IF(Equips_usuari!D40="","",Equips_usuari!D40) -> U17 | E40: =IF(Equips_usuari!F40="","",Equips_usuari!F40) -> NO | F40: =IF($C40="","",SUMIFS(Resultats_jugadores!$C:$C,Resultats_jugadores!$A:$A,$A40,Resultats_jugadores!$B:$B,$C40)) -> 0 | G40: =IF($C40="","",SUMIFS(Resultats_jugadores!$D:$D,Resultats_jugadores!$A:$A,$A40,Resultats_jugadores!$B:$B,$C40)) -> 0 | H40: =IF($C40="","",N($F40)-N($G40)) -> 0 | I40: {=IF($C40="","",IFERROR(INDEX(Partits!$C:$C,MATCH($A40&"_"&$D40,Partits!$D:$D,0)),""))} -> V | J40: =IF($C40="","",IF(AND($I40="V",N($H40)>0),1.2,1)) -> 1 | K40: =IF($C40="","",N($H40)*$J40) -> 0 | L40: =IF($C40="","",IF($E40="SI",2,1)) -> 1 | M40: =IF($C40="","",$K40*$L40) -> 0
...

Sheet Classificacio
A1: Jornada | B1: Usuari | C1: Punts_equip | D1: Punts_preguntes | E1: Punts_totals
A2: 1 | B2: U13 | C2: 15 | D2: 0 | E2: =N($C2)+N($D2) -> 15
A3: 1 | B3: U14 | C3: 15 | D3: =SUMIFS(Respostes_usuari!$F:$F,Respostes_usuari!$A:$A,$A3,Respostes_usuari!$B:$B,$B3) -> 0 | E3: =N($C3)+N($D3) -> 15
A4: 1 | B4: U15 | C4: 15 | D4: =SUMIFS(Respostes_usuari!$F:$F,Respostes_usuari!$A:$A,$A4,Respostes_usuari!$B:$B,$B4) -> 0 | E4: =N($C4)+N($D4) -> 15
A5: 1 | B5: U16 | C5: 10 | D5: =SUMIFS(Respostes_usuari!$F:$F,Respostes_usuari!$A:$A,$A5,Respostes_usuari!$B:$B,$B5) -> 0 | E5: =N($C5)+N($D5) -> 10
A6: 1 | B6: U17+SFB | C6: 10 | D6: =SUMIFS(Respostes_usuari!$F:$F,Respostes_usuari!$A:$A,$A6,Respostes_usuari!$B:$B,$B6) -> 0 | E6: =N($C6)+N($D6) -> 10
A7: 1 | B7: U18+DE | C7: 20 | D7: =SUMIFS(Respostes_usuari!$F:$F,Respostes_usuari!$A:$A,$A7,Respostes_usuari!$B:$B,$B7) -> 0 | E7: =N($C7)+N($D7) -> 20
A8: 1 | B8: LF2 | C8: =SUMIFS(Calcul_puntuacio!$M:$M,Calcul_puntuacio!$A:$A,$A8,Calcul_puntuacio!$B:$B,$B8) -> 85.2 | D8: =SUMIFS(Respostes_usuari!$F:$F,Respostes_usuari!$A:$A,$A8,Respostes_usuari!$B:$B,$B8) -> 0 | E8: =N($C8)+N($D8) -> 85.2
A9: 2 | B9: U13 | C9: =SUMIFS(Calcul_puntuacio!$M:$M,Calcul_puntuacio!$A:$A,$A9,Calcul_puntuacio!$B:$B,$B9) -> 0 | D9: =SUMIFS(Respostes_usuari!$F:$F,Respostes_usuari!$A:$A,$A9,Respostes_usuari!$B:$B,$B9) -> 0 | E9: =N($C9)+N($D9) -> 0
A10: 2 | B10: U14 | C10: =SUMIFS(Calcul_puntuacio!$M:$M,Calcul_puntuacio!$A:$A,$A10,Calcul_puntuacio!$B:$B,$B10) -> 0 | D10: =SUMIFS(Respostes_usuari!$F:$F,Respostes_usuari!$A:$A,$A10,Respostes_usuari!$B:$B,$B10) -> 0 | E10: =N($C10)+N($D10) -> 0
A11: 2 | B11: U15 | C11: =SUMIFS(Calcul_puntuacio!$M:$M,Calcul_puntuacio!$A:$A,$A11,Calcul_puntuacio!$B:$B,$B11) -> 0 | D11: =SUMIFS(Respostes_usuari!$F:$F,Respostes_usuari!$A:$A,$A11,Respostes_usuari!$B:$B,$B11) -> 0 | E11: =N($C11)+N($D11) -> 0
A12: 2 | B12: U16 | C12: =SUMIFS(Calcul_puntuacio!$M:$M,Calcul_puntuacio!$A:$A,$A12,Calcul_puntuacio!$B:$B,$B12) -> 0 | D12: =SUMIFS(Respostes_usuari!$F:$F,Respostes_usuari!$A:$A,$A12,Respostes_usuari!$B:$B,$B12) -> 0 | E12: =N($C12)+N($D12) -> 0
A13: 2 | B13: U17+SFB | C13: =SUMIFS(Calcul_puntuacio!$M:$M,Calcul_puntuacio!$A:$A,$A13,Calcul_puntuacio!$B:$B,$B13) -> 0 | D13: =SUMIFS(Respostes_usuari!$F:$F,Respostes_usuari!$A:$A,$A13,Respostes_usuari!$B:$B,$B13) -> 0 | E13: =N($C13)+N($D13) -> 0
A14: 2 | B14: U18+DE | C14: =SUMIFS(Calcul_puntuacio!$M:$M,Calcul_puntuacio!$A:$A,$A14,Calcul_puntuacio!$B:$B,$B14) -> 0 | D14: =SUMIFS(Respostes_usuari!$F:$F,Respostes_usuari!$A:$A,$A14,Respostes_usuari!$B:$B,$B14) -> 0 | E14: =N($C14)+N($D14) -> 0
A15: 2 | B15: LF2 | C15: =SUMIFS(Calcul_puntuacio!$M:$M,Calcul_puntuacio!$A:$A,$A15,Calcul_puntuacio!$B:$B,$B15) -> 0 | D15: =SUMIFS(Respostes_usuari!$F:$F,Respostes_usuari!$A:$A,$A15,Respostes_usuari!$B:$B,$B15) -> 0 | E15: =N($C15)+N($D15) -> 0
A16: 3 | B16: U13 | C16: =SUMIFS(Calcul_puntuacio!$M:$M,Calcul_puntuacio!$A:$A,$A16,Calcul_puntuacio!$B:$B,$B16) -> 0 | D16: =SUMIFS(Respostes_usuari!$F:$F,Respostes_usuari!$A:$A,$A16,Respostes_usuari!$B:$B,$B16) -> 0 | E16: =N($C16)+N($D16) -> 0
A17: 3 | B17: U14 | C17: =SUMIFS(Calcul_puntuacio!$M:$M,Calcul_puntuacio!$A:$A,$A17,Calcul_puntuacio!$B:$B,$B17) -> 0 | D17: =SUMIFS(Respostes_usuari!$F:$F,Respostes_usuari!$A:$A,$A17,Respostes_usuari!$B:$B,$B17) -> 0 | E17: =N($C17)+N($D17) -> 0
A18: 3 | B18: U15 | C18: =SUMIFS(Calcul_puntuacio!$M:$M,Calcul_puntuacio!$A:$A,$A18,Calcul_puntuacio!$B:$B,$B18) -> 0 | D18: =SUMIFS(Respostes_usuari!$F:$F,Respostes_usuari!$A:$A,$A18,Respostes_usuari!$B:$B,$B18) -> 0 | E18: =N($C18)+N($D18) -> 0
A19: 3 | B19: U16 | C19: =SUMIFS(Calcul_puntuacio!$M:$M,Calcul_puntuacio!$A:$A,$A19,Calcul_puntuacio!$B:$B,$B19) -> 0 | D19: =SUMIFS(Respostes_usuari!$F:$F,Respostes_usuari!$A:$A,$A19,Respostes_usuari!$B:$B,$B19) -> 0 | E19: =N($C19)+N($D19) -> 0
... A71: 10 | B71: LF2 | C71: =SUMIFS(Calcul_puntuacio!$M:$M,Calcul_puntuacio!$A:$A,$A71,Calcul_puntuacio!$B:$B,$B71) -> 0 | D71: =SUMIFS(Respostes_usuari!$F:$F,Respostes_usuari!$A:$A,$A71,Respostes_usuari!$B:$B,$B71) -> 0 | E71: =N($C71)+N($D71) -> 0

Sheet Classificacio_global
A1: Usuari | B1: Punts_totals_acumulats
A2: U13 | B2: =SUMIF(Classificacio!$B:$B,$A2,Classificacio!$E:$E) -> 15
A3: U14 | B3: =SUMIF(Classificacio!$B:$B,$A3,Classificacio!$E:$E) -> 15
A4: U15 | B4: =SUMIF(Classificacio!$B:$B,$A4,Classificacio!$E:$E) -> 15
A5: U16 | B5: =SUMIF(Classificacio!$B:$B,$A5,Classificacio!$E:$E) -> 10
A6: U17+SFB | B6: =SUMIF(Classificacio!$B:$B,$A6,Classificacio!$E:$E) -> 10
A7: U18+DE | B7: =SUMIF(Classificacio!$B:$B,$A7,Classificacio!$E:$E) -> 20
A8: LF2 | B8: =SUMIF(Classificacio!$B:$B,$A8,Classificacio!$E:$E) -> 85.2
